============================= test session starts =============================
platform win32 -- Python 3.12.3, pytest-8.3.2, pluggy-1.6.0 -- C:\Python312\python.exe
cachedir: .pytest_cache
rootdir: X:\pet_projs\FoodRadar2
configfile: pytest.ini
testpaths: backend/tests
collecting ... collected 0 items / 2 errors

=================================== ERRORS ====================================
_______________ ERROR collecting backend/tests/test_courier.py ________________
ImportError while importing test module 'X:\pet_projs\FoodRadar2\backend\tests\test_courier.py'.
Hint: make sure your test modules/packages have valid Python names.
Traceback:
C:\Python312\Lib\importlib\__init__.py:90: in import_module
    return _bootstrap._gcd_import(name[level:], package, level)
backend\tests\test_courier.py:8: in <module>
    from .factories import (
E   ImportError: attempted relative import with no known parent package
_______________ ERROR collecting backend/tests/test_payments.py _______________
ImportError while importing test module 'X:\pet_projs\FoodRadar2\backend\tests\test_payments.py'.
Hint: make sure your test modules/packages have valid Python names.
Traceback:
C:\Python312\Lib\importlib\__init__.py:90: in import_module
    return _bootstrap._gcd_import(name[level:], package, level)
backend\tests\test_payments.py:6: in <module>
    from .factories import UserFactory, RestaurantFactory, OrderFactory
E   ImportError: attempted relative import with no known parent package
============================== warnings summary ===============================
C:\Python312\Lib\site-packages\_pytest\config\__init__.py:1437
  C:\Python312\Lib\site-packages\_pytest\config\__init__.py:1437: PytestConfigWarning: Unknown config option: DJANGO_SETTINGS_MODULE
  
    self._warn_or_fail_if_strict(f"Unknown config option: {key}\n")

-- Docs: https://docs.pytest.org/en/stable/how-to/capture-warnings.html
=========================== short test summary info ===========================
ERROR backend/tests/test_courier.py
ERROR backend/tests/test_payments.py
!!!!!!!!!!!!!!!!!!! Interrupted: 2 errors during collection !!!!!!!!!!!!!!!!!!!
======================== 1 warning, 2 errors in 0.20s =========================
